2019-09-24 18:04:42 WARNING (Recorder) [homeassistant.components.recorder] Ended unfinished session (id=18 from 2019-09-24 16:51:21.862420)
2019-09-24 18:04:46 ERROR (MainThread) [homeassistant.config] Invalid config for [hue]: [sensor] is an invalid option for [hue]. Check: hue->hue->sensor. (See /config/configuration.yaml, line 18). Please check the docs at https://home-assistant.io/components/hue/
2019-09-24 18:04:46 ERROR (MainThread) [homeassistant.setup] Setup failed for hue: Invalid config.
2019-09-24 18:04:46 WARNING (SyncWorker_9) [homeassistant.components.influxdb] Database host is not accessible due to '403: {"error":"\"homeassistant\" user is not authorized to write to database \"homeassistant\""}
', please check your entries in the configuration file (host, port, etc.) and verify that the database exists and is READ/WRITE. Retrying again in 60 seconds.
2019-09-24 18:05:48 WARNING (SyncWorker_5) [homeassistant.components.influxdb] Database host is not accessible due to '403: {"error":"\"homeassistant\" user is not authorized to write to database \"homeassistant\""}
', please check your entries in the configuration file (host, port, etc.) and verify that the database exists and is READ/WRITE. Retrying again in 60 seconds.
2019-09-24 18:06:49 WARNING (SyncWorker_0) [homeassistant.components.influxdb] Database host is not accessible due to '403: {"error":"\"homeassistant\" user is not authorized to write to database \"homeassistant\""}
', please check your entries in the configuration file (host, port, etc.) and verify that the database exists and is READ/WRITE. Retrying again in 60 seconds.
2019-09-24 18:07:50 WARNING (SyncWorker_7) [homeassistant.components.influxdb] Database host is not accessible due to '403: {"error":"\"homeassistant\" user is not authorized to write to database \"homeassistant\""}
', please check your entries in the configuration file (host, port, etc.) and verify that the database exists and is READ/WRITE. Retrying again in 60 seconds.
2019-09-24 18:08:51 WARNING (SyncWorker_2) [homeassistant.components.influxdb] Database host is not accessible due to '403: {"error":"\"homeassistant\" user is not authorized to write to database \"homeassistant\""}
', please check your entries in the configuration file (host, port, etc.) and verify that the database exists and is READ/WRITE. Retrying again in 60 seconds.
2019-09-24 18:09:52 WARNING (SyncWorker_0) [homeassistant.components.influxdb] Database host is not accessible due to '403: {"error":"\"homeassistant\" user is not authorized to write to database \"homeassistant\""}
', please check your entries in the configuration file (host, port, etc.) and verify that the database exists and is READ/WRITE. Retrying again in 60 seconds.
2019-09-24 18:10:53 WARNING (SyncWorker_14) [homeassistant.components.influxdb] Database host is not accessible due to '403: {"error":"\"homeassistant\" user is not authorized to write to database \"homeassistant\""}
', please check your entries in the configuration file (host, port, etc.) and verify that the database exists and is READ/WRITE. Retrying again in 60 seconds.
2019-09-24 18:11:54 WARNING (SyncWorker_5) [homeassistant.components.influxdb] Database host is not accessible due to '403: {"error":"\"homeassistant\" user is not authorized to write to database \"homeassistant\""}
', please check your entries in the configuration file (host, port, etc.) and verify that the database exists and is READ/WRITE. Retrying again in 60 seconds.
2019-09-24 18:12:55 WARNING (SyncWorker_6) [homeassistant.components.influxdb] Database host is not accessible due to '403: {"error":"\"homeassistant\" user is not authorized to write to database \"homeassistant\""}
', please check your entries in the configuration file (host, port, etc.) and verify that the database exists and is READ/WRITE. Retrying again in 60 seconds.
2019-09-24 18:13:56 WARNING (SyncWorker_0) [homeassistant.components.influxdb] Database host is not accessible due to '403: {"error":"\"homeassistant\" user is not authorized to write to database \"homeassistant\""}
', please check your entries in the configuration file (host, port, etc.) and verify that the database exists and is READ/WRITE. Retrying again in 60 seconds.
2019-09-24 18:14:57 WARNING (SyncWorker_15) [homeassistant.components.influxdb] Database host is not accessible due to '403: {"error":"\"homeassistant\" user is not authorized to write to database \"homeassistant\""}
', please check your entries in the configuration file (host, port, etc.) and verify that the database exists and is READ/WRITE. Retrying again in 60 seconds.
2019-09-24 18:15:43 WARNING (zeroconf-ServiceBrowser__googlecast._tcp.local.) [zeroconf] Exception occurred:
Traceback (most recent call last):
  File "/usr/local/lib/python3.7/site-packages/zeroconf.py", line 2245, in send
    bytes_sent = s.sendto(packet, 0, (addr, port))
PermissionError: [Errno 1] Operation not permitted
2019-09-24 18:15:58 WARNING (SyncWorker_7) [homeassistant.components.influxdb] Database host is not accessible due to '403: {"error":"\"homeassistant\" user is not authorized to write to database \"homeassistant\""}
', please check your entries in the configuration file (host, port, etc.) and verify that the database exists and is READ/WRITE. Retrying again in 60 seconds.
2019-09-24 18:16:59 WARNING (SyncWorker_5) [homeassistant.components.influxdb] Database host is not accessible due to '403: {"error":"\"homeassistant\" user is not authorized to write to database \"homeassistant\""}
', please check your entries in the configuration file (host, port, etc.) and verify that the database exists and is READ/WRITE. Retrying again in 60 seconds.
2019-09-24 18:18:00 WARNING (SyncWorker_2) [homeassistant.components.influxdb] Database host is not accessible due to '403: {"error":"\"homeassistant\" user is not authorized to write to database \"homeassistant\""}
', please check your entries in the configuration file (host, port, etc.) and verify that the database exists and is READ/WRITE. Retrying again in 60 seconds.
2019-09-24 18:19:01 WARNING (SyncWorker_0) [homeassistant.components.influxdb] Database host is not accessible due to '403: {"error":"\"homeassistant\" user is not authorized to write to database \"homeassistant\""}
', please check your entries in the configuration file (host, port, etc.) and verify that the database exists and is READ/WRITE. Retrying again in 60 seconds.
2019-09-24 18:20:02 WARNING (SyncWorker_17) [homeassistant.components.influxdb] Database host is not accessible due to '403: {"error":"\"homeassistant\" user is not authorized to write to database \"homeassistant\""}
', please check your entries in the configuration file (host, port, etc.) and verify that the database exists and is READ/WRITE. Retrying again in 60 seconds.
2019-09-24 18:21:03 WARNING (SyncWorker_11) [homeassistant.components.influxdb] Database host is not accessible due to '403: {"error":"\"homeassistant\" user is not authorized to write to database \"homeassistant\""}
', please check your entries in the configuration file (host, port, etc.) and verify that the database exists and is READ/WRITE. Retrying again in 60 seconds.
2019-09-24 18:22:04 WARNING (SyncWorker_8) [homeassistant.components.influxdb] Database host is not accessible due to '403: {"error":"\"homeassistant\" user is not authorized to write to database \"homeassistant\""}
', please check your entries in the configuration file (host, port, etc.) and verify that the database exists and is READ/WRITE. Retrying again in 60 seconds.
2019-09-24 18:23:05 WARNING (SyncWorker_1) [homeassistant.components.influxdb] Database host is not accessible due to '403: {"error":"\"homeassistant\" user is not authorized to write to database \"homeassistant\""}
', please check your entries in the configuration file (host, port, etc.) and verify that the database exists and is READ/WRITE. Retrying again in 60 seconds.
2019-09-24 18:24:06 WARNING (SyncWorker_10) [homeassistant.components.influxdb] Database host is not accessible due to '403: {"error":"\"homeassistant\" user is not authorized to write to database \"homeassistant\""}
', please check your entries in the configuration file (host, port, etc.) and verify that the database exists and is READ/WRITE. Retrying again in 60 seconds.
2019-09-24 18:25:07 WARNING (SyncWorker_17) [homeassistant.components.influxdb] Database host is not accessible due to '403: {"error":"\"homeassistant\" user is not authorized to write to database \"homeassistant\""}
', please check your entries in the configuration file (host, port, etc.) and verify that the database exists and is READ/WRITE. Retrying again in 60 seconds.
2019-09-24 18:26:08 WARNING (SyncWorker_12) [homeassistant.components.influxdb] Database host is not accessible due to '403: {"error":"\"homeassistant\" user is not authorized to write to database \"homeassistant\""}
', please check your entries in the configuration file (host, port, etc.) and verify that the database exists and is READ/WRITE. Retrying again in 60 seconds.
2019-09-24 18:26:55 ERROR (MainThread) [homeassistant.components.hassio] Invalid config for [hue]: [sensor] is an invalid option for [hue]. Check: hue->hue->sensor. (See /config/configuration.yaml, line 18). Please check the docs at https://home-assistant.io/components/hue/
2019-09-24 18:27:09 WARNING (SyncWorker_1) [homeassistant.components.influxdb] Database host is not accessible due to '403: {"error":"\"homeassistant\" user is not authorized to write to database \"homeassistant\""}
', please check your entries in the configuration file (host, port, etc.) and verify that the database exists and is READ/WRITE. Retrying again in 60 seconds.
2019-09-24 18:28:10 WARNING (SyncWorker_15) [homeassistant.components.influxdb] Database host is not accessible due to '403: {"error":"\"homeassistant\" user is not authorized to write to database \"homeassistant\""}
', please check your entries in the configuration file (host, port, etc.) and verify that the database exists and is READ/WRITE. Retrying again in 60 seconds.
2019-09-24 18:29:00 ERROR (MainThread) [homeassistant.core] Error doing job: Task exception was never retrieved
Traceback (most recent call last):
  File "/usr/src/homeassistant/homeassistant/components/cloud/alexa_config.py", line 280, in _handle_entity_registry_updated
    await self._sync_helper(to_update, to_remove)
  File "/usr/src/homeassistant/homeassistant/components/cloud/alexa_config.py", line 234, in _sync_helper
    await self.async_get_access_token()
  File "/usr/src/homeassistant/homeassistant/components/cloud/alexa_config.py", line 123, in async_get_access_token
    raise RequireRelink
homeassistant.components.cloud.const.RequireRelink
2019-09-24 18:29:05 ERROR (Thread-7) [pychromecast.socket_client] [Study group:42452] Error reading from socket.
2019-09-24 18:29:05 WARNING (Thread-7) [pychromecast.socket_client] [Study group:42452] Error communicating with socket, resetting connection
2019-09-24 18:29:11 WARNING (SyncWorker_5) [homeassistant.components.influxdb] Database host is not accessible due to '403: {"error":"\"homeassistant\" user is not authorized to write to database \"homeassistant\""}
', please check your entries in the configuration file (host, port, etc.) and verify that the database exists and is READ/WRITE. Retrying again in 60 seconds.
2019-09-24 18:30:12 WARNING (SyncWorker_6) [homeassistant.components.influxdb] Database host is not accessible due to '403: {"error":"\"homeassistant\" user is not authorized to write to database \"homeassistant\""}
', please check your entries in the configuration file (host, port, etc.) and verify that the database exists and is READ/WRITE. Retrying again in 60 seconds.
2019-09-24 18:30:50 ERROR (MainThread) [homeassistant.components.hassio] Invalid config for [hue]: [sensor] is an invalid option for [hue]. Check: hue->hue->sensor. (See /config/configuration.yaml, line 18). Please check the docs at https://home-assistant.io/components/hue/
2019-09-24 18:31:13 WARNING (SyncWorker_9) [homeassistant.components.influxdb] Database host is not accessible due to '403: {"error":"\"homeassistant\" user is not authorized to write to database \"homeassistant\""}
', please check your entries in the configuration file (host, port, etc.) and verify that the database exists and is READ/WRITE. Retrying again in 60 seconds.
2019-09-24 18:32:14 WARNING (SyncWorker_0) [homeassistant.components.influxdb] Database host is not accessible due to '403: {"error":"\"homeassistant\" user is not authorized to write to database \"homeassistant\""}
', please check your entries in the configuration file (host, port, etc.) and verify that the database exists and is READ/WRITE. Retrying again in 60 seconds.
2019-09-24 18:33:15 WARNING (SyncWorker_19) [homeassistant.components.influxdb] Database host is not accessible due to '403: {"error":"\"homeassistant\" user is not authorized to write to database \"homeassistant\""}
', please check your entries in the configuration file (host, port, etc.) and verify that the database exists and is READ/WRITE. Retrying again in 60 seconds.
2019-09-24 18:33:53 ERROR (MainThread) [homeassistant.components.hassio] Invalid config for [hue]: [sensor] is an invalid option for [hue]. Check: hue->hue->sensor. (See /config/configuration.yaml, line 18). Please check the docs at https://home-assistant.io/components/hue/
2019-09-24 18:34:16 WARNING (SyncWorker_13) [homeassistant.components.influxdb] Database host is not accessible due to 'HTTPConnectionPool(host='localhost', port=8086): Max retries exceeded with url: /write?db=homeassistant (Caused by NewConnectionError('<urllib3.connection.HTTPConnection object at 0x6e64f7f0>: Failed to establish a new connection: [Errno 111] Connection refused'))', please check your entries in the configuration file (host, port, etc.) and verify that the database exists and is READ/WRITE. Retrying again in 60 seconds.
2019-09-24 18:35:17 WARNING (SyncWorker_12) [homeassistant.components.influxdb] Database host is not accessible due to 'HTTPConnectionPool(host='localhost', port=8086): Max retries exceeded with url: /write?db=homeassistant (Caused by NewConnectionError('<urllib3.connection.HTTPConnection object at 0x6e636330>: Failed to establish a new connection: [Errno 111] Connection refused'))', please check your entries in the configuration file (host, port, etc.) and verify that the database exists and is READ/WRITE. Retrying again in 60 seconds.
2019-09-24 18:36:18 WARNING (SyncWorker_19) [homeassistant.components.influxdb] Database host is not accessible due to 'HTTPConnectionPool(host='localhost', port=8086): Max retries exceeded with url: /write?db=homeassistant (Caused by NewConnectionError('<urllib3.connection.HTTPConnection object at 0x6e45d7d0>: Failed to establish a new connection: [Errno 111] Connection refused'))', please check your entries in the configuration file (host, port, etc.) and verify that the database exists and is READ/WRITE. Retrying again in 60 seconds.
2019-09-24 18:36:50 ERROR (MainThread) [homeassistant.components.hassio] Invalid config for [hue]: [sensor] is an invalid option for [hue]. Check: hue->hue->sensor. (See /config/configuration.yaml, line 18). Please check the docs at https://home-assistant.io/components/hue/
2019-09-24 18:37:19 WARNING (SyncWorker_7) [homeassistant.components.influxdb] Database host is not accessible due to 'HTTPConnectionPool(host='localhost', port=8086): Max retries exceeded with url: /write?db=homeassistant (Caused by NewConnectionError('<urllib3.connection.HTTPConnection object at 0x6e8b4190>: Failed to establish a new connection: [Errno 111] Connection refused'))', please check your entries in the configuration file (host, port, etc.) and verify that the database exists and is READ/WRITE. Retrying again in 60 seconds.
2019-09-24 18:38:20 WARNING (SyncWorker_17) [homeassistant.components.influxdb] Database host is not accessible due to 'HTTPConnectionPool(host='localhost', port=8086): Max retries exceeded with url: /write?db=homeassistant (Caused by NewConnectionError('<urllib3.connection.HTTPConnection object at 0x6e706590>: Failed to establish a new connection: [Errno 111] Connection refused'))', please check your entries in the configuration file (host, port, etc.) and verify that the database exists and is READ/WRITE. Retrying again in 60 seconds.
2019-09-24 18:39:21 WARNING (SyncWorker_0) [homeassistant.components.influxdb] Database host is not accessible due to 'HTTPConnectionPool(host='localhost', port=8086): Max retries exceeded with url: /write?db=homeassistant (Caused by NewConnectionError('<urllib3.connection.HTTPConnection object at 0x6e62c830>: Failed to establish a new connection: [Errno 111] Connection refused'))', please check your entries in the configuration file (host, port, etc.) and verify that the database exists and is READ/WRITE. Retrying again in 60 seconds.
2019-09-24 18:40:07 WARNING (Thread-2) [pychromecast.socket_client] [Study speaker:8009] Heartbeat timeout, resetting connection
2019-09-24 18:40:11 WARNING (Thread-4) [pychromecast.socket_client] [Study group:42968] Heartbeat timeout, resetting connection
2019-09-24 18:40:11 WARNING (Thread-3) [pychromecast.socket_client] [Home group:42209] Heartbeat timeout, resetting connection
2019-09-24 18:40:22 WARNING (SyncWorker_12) [homeassistant.components.influxdb] Database host is not accessible due to 'HTTPConnectionPool(host='localhost', port=8086): Max retries exceeded with url: /write?db=homeassistant (Caused by NewConnectionError('<urllib3.connection.HTTPConnection object at 0x6e385d70>: Failed to establish a new connection: [Errno 111] Connection refused'))', please check your entries in the configuration file (host, port, etc.) and verify that the database exists and is READ/WRITE. Retrying again in 60 seconds.
2019-09-24 18:40:37 ERROR (Thread-2) [pychromecast.socket_client] [Study speaker:8009] Failed to connect to service Google-Home-Mini-ab1649bed7344715e5d99641023cd7f1._googlecast._tcp.local., retrying in 5.0s
2019-09-24 18:41:23 WARNING (SyncWorker_9) [homeassistant.components.influxdb] Database host is not accessible due to 'HTTPConnectionPool(host='localhost', port=8086): Max retries exceeded with url: /write?db=homeassistant (Caused by NewConnectionError('<urllib3.connection.HTTPConnection object at 0x6e5de990>: Failed to establish a new connection: [Errno 111] Connection refused'))', please check your entries in the configuration file (host, port, etc.) and verify that the database exists and is READ/WRITE. Retrying again in 60 seconds.
2019-09-24 18:42:24 WARNING (SyncWorker_13) [homeassistant.components.influxdb] Database host is not accessible due to 'HTTPConnectionPool(host='localhost', port=8086): Max retries exceeded with url: /write?db=homeassistant (Caused by NewConnectionError('<urllib3.connection.HTTPConnection object at 0x719af630>: Failed to establish a new connection: [Errno 111] Connection refused'))', please check your entries in the configuration file (host, port, etc.) and verify that the database exists and is READ/WRITE. Retrying again in 60 seconds.
2019-09-24 18:43:25 WARNING (SyncWorker_1) [homeassistant.components.influxdb] Database host is not accessible due to 'HTTPConnectionPool(host='localhost', port=8086): Max retries exceeded with url: /write?db=homeassistant (Caused by NewConnectionError('<urllib3.connection.HTTPConnection object at 0x6e6f7df0>: Failed to establish a new connection: [Errno 111] Connection refused'))', please check your entries in the configuration file (host, port, etc.) and verify that the database exists and is READ/WRITE. Retrying again in 60 seconds.
2019-09-24 18:44:26 WARNING (SyncWorker_0) [homeassistant.components.influxdb] Database host is not accessible due to 'HTTPConnectionPool(host='localhost', port=8086): Max retries exceeded with url: /write?db=homeassistant (Caused by NewConnectionError('<urllib3.connection.HTTPConnection object at 0x6e64f3f0>: Failed to establish a new connection: [Errno 111] Connection refused'))', please check your entries in the configuration file (host, port, etc.) and verify that the database exists and is READ/WRITE. Retrying again in 60 seconds.
2019-09-24 18:45:27 WARNING (SyncWorker_12) [homeassistant.components.influxdb] Database host is not accessible due to 'HTTPConnectionPool(host='localhost', port=8086): Max retries exceeded with url: /write?db=homeassistant (Caused by NewConnectionError('<urllib3.connection.HTTPConnection object at 0x6e3853b0>: Failed to establish a new connection: [Errno 111] Connection refused'))', please check your entries in the configuration file (host, port, etc.) and verify that the database exists and is READ/WRITE. Retrying again in 60 seconds.
2019-09-24 18:45:31 ERROR (Thread-4) [pychromecast.socket_client] [Study group:42968] Error reading from socket.
2019-09-24 18:45:31 WARNING (Thread-4) [pychromecast.socket_client] [Study group:42968] Error communicating with socket, resetting connection
2019-09-24 18:45:31 ERROR (Thread-3) [pychromecast.socket_client] [Home group:42209] Error reading from socket.
2019-09-24 18:45:31 ERROR (Thread-4) [pychromecast.socket_client] [Study group:42968] Failed to connect to service Google-Cast-Group-8814ec1493a5480cadac4b1ddaae9179._googlecast._tcp.local., retrying in 5.0s
2019-09-24 18:45:31 WARNING (Thread-3) [pychromecast.socket_client] [Home group:42209] Error communicating with socket, resetting connection
2019-09-24 18:46:28 WARNING (SyncWorker_9) [homeassistant.components.influxdb] Database host is not accessible due to 'HTTPConnectionPool(host='localhost', port=8086): Max retries exceeded with url: /write?db=homeassistant (Caused by NewConnectionError('<urllib3.connection.HTTPConnection object at 0x6e6329d0>: Failed to establish a new connection: [Errno 111] Connection refused'))', please check your entries in the configuration file (host, port, etc.) and verify that the database exists and is READ/WRITE. Retrying again in 60 seconds.
2019-09-24 18:47:29 WARNING (SyncWorker_13) [homeassistant.components.influxdb] Database host is not accessible due to 'HTTPConnectionPool(host='localhost', port=8086): Max retries exceeded with url: /write?db=homeassistant (Caused by NewConnectionError('<urllib3.connection.HTTPConnection object at 0x6e47f810>: Failed to establish a new connection: [Errno 111] Connection refused'))', please check your entries in the configuration file (host, port, etc.) and verify that the database exists and is READ/WRITE. Retrying again in 60 seconds.
2019-09-24 18:48:30 WARNING (SyncWorker_1) [homeassistant.components.influxdb] Database host is not accessible due to 'HTTPConnectionPool(host='localhost', port=8086): Max retries exceeded with url: /write?db=homeassistant (Caused by NewConnectionError('<urllib3.connection.HTTPConnection object at 0x6e632550>: Failed to establish a new connection: [Errno 111] Connection refused'))', please check your entries in the configuration file (host, port, etc.) and verify that the database exists and is READ/WRITE. Retrying again in 60 seconds.
2019-09-24 18:49:31 WARNING (SyncWorker_0) [homeassistant.components.influxdb] Database host is not accessible due to 'HTTPConnectionPool(host='localhost', port=8086): Max retries exceeded with url: /write?db=homeassistant (Caused by NewConnectionError('<urllib3.connection.HTTPConnection object at 0x6e47f530>: Failed to establish a new connection: [Errno 111] Connection refused'))', please check your entries in the configuration file (host, port, etc.) and verify that the database exists and is READ/WRITE. Retrying again in 60 seconds.
2019-09-24 18:50:32 WARNING (SyncWorker_4) [homeassistant.components.influxdb] Database host is not accessible due to 'HTTPConnectionPool(host='localhost', port=8086): Max retries exceeded with url: /write?db=homeassistant (Caused by NewConnectionError('<urllib3.connection.HTTPConnection object at 0x6e39c150>: Failed to establish a new connection: [Errno 111] Connection refused'))', please check your entries in the configuration file (host, port, etc.) and verify that the database exists and is READ/WRITE. Retrying again in 60 seconds.
2019-09-24 18:51:33 WARNING (SyncWorker_2) [homeassistant.components.influxdb] Database host is not accessible due to 'HTTPConnectionPool(host='localhost', port=8086): Max retries exceeded with url: /write?db=homeassistant (Caused by NewConnectionError('<urllib3.connection.HTTPConnection object at 0x6e6c4970>: Failed to establish a new connection: [Errno 111] Connection refused'))', please check your entries in the configuration file (host, port, etc.) and verify that the database exists and is READ/WRITE. Retrying again in 60 seconds.
2019-09-24 18:52:34 WARNING (SyncWorker_18) [homeassistant.components.influxdb] Database host is not accessible due to 'HTTPConnectionPool(host='localhost', port=8086): Max retries exceeded with url: /write?db=homeassistant (Caused by NewConnectionError('<urllib3.connection.HTTPConnection object at 0x6e69efb0>: Failed to establish a new connection: [Errno 111] Connection refused'))', please check your entries in the configuration file (host, port, etc.) and verify that the database exists and is READ/WRITE. Retrying again in 60 seconds.
2019-09-24 18:53:35 WARNING (SyncWorker_3) [homeassistant.components.influxdb] Database host is not accessible due to 'HTTPConnectionPool(host='localhost', port=8086): Max retries exceeded with url: /write?db=homeassistant (Caused by NewConnectionError('<urllib3.connection.HTTPConnection object at 0x6e628f50>: Failed to establish a new connection: [Errno 111] Connection refused'))', please check your entries in the configuration file (host, port, etc.) and verify that the database exists and is READ/WRITE. Retrying again in 60 seconds.
2019-09-24 18:54:36 WARNING (SyncWorker_11) [homeassistant.components.influxdb] Database host is not accessible due to 'HTTPConnectionPool(host='localhost', port=8086): Max retries exceeded with url: /write?db=homeassistant (Caused by NewConnectionError('<urllib3.connection.HTTPConnection object at 0x6e628f90>: Failed to establish a new connection: [Errno 111] Connection refused'))', please check your entries in the configuration file (host, port, etc.) and verify that the database exists and is READ/WRITE. Retrying again in 60 seconds.
2019-09-24 18:55:37 WARNING (SyncWorker_18) [homeassistant.components.influxdb] Database host is not accessible due to 'HTTPConnectionPool(host='localhost', port=8086): Max retries exceeded with url: /write?db=homeassistant (Caused by NewConnectionError('<urllib3.connection.HTTPConnection object at 0x6e461310>: Failed to establish a new connection: [Errno 111] Connection refused'))', please check your entries in the configuration file (host, port, etc.) and verify that the database exists and is READ/WRITE. Retrying again in 60 seconds.
2019-09-24 18:56:38 WARNING (SyncWorker_10) [homeassistant.components.influxdb] Database host is not accessible due to 'HTTPConnectionPool(host='localhost', port=8086): Max retries exceeded with url: /write?db=homeassistant (Caused by NewConnectionError('<urllib3.connection.HTTPConnection object at 0x6e6c4630>: Failed to establish a new connection: [Errno 111] Connection refused'))', please check your entries in the configuration file (host, port, etc.) and verify that the database exists and is READ/WRITE. Retrying again in 60 seconds.
2019-09-24 18:57:39 WARNING (SyncWorker_5) [homeassistant.components.influxdb] Database host is not accessible due to 'HTTPConnectionPool(host='localhost', port=8086): Max retries exceeded with url: /write?db=homeassistant (Caused by NewConnectionError('<urllib3.connection.HTTPConnection object at 0x6e385a90>: Failed to establish a new connection: [Errno 111] Connection refused'))', please check your entries in the configuration file (host, port, etc.) and verify that the database exists and is READ/WRITE. Retrying again in 60 seconds.
2019-09-24 18:58:40 WARNING (SyncWorker_2) [homeassistant.components.influxdb] Database host is not accessible due to 'HTTPConnectionPool(host='localhost', port=8086): Max retries exceeded with url: /write?db=homeassistant (Caused by NewConnectionError('<urllib3.connection.HTTPConnection object at 0x6e142750>: Failed to establish a new connection: [Errno 111] Connection refused'))', please check your entries in the configuration file (host, port, etc.) and verify that the database exists and is READ/WRITE. Retrying again in 60 seconds.
2019-09-24 18:59:41 WARNING (SyncWorker_13) [homeassistant.components.influxdb] Database host is not accessible due to 'HTTPConnectionPool(host='localhost', port=8086): Max retries exceeded with url: /write?db=homeassistant (Caused by NewConnectionError('<urllib3.connection.HTTPConnection object at 0x6e2d2eb0>: Failed to establish a new connection: [Errno 111] Connection refused'))', please check your entries in the configuration file (host, port, etc.) and verify that the database exists and is READ/WRITE. Retrying again in 60 seconds.
2019-09-24 19:00:42 WARNING (SyncWorker_16) [homeassistant.components.influxdb] Database host is not accessible due to 'HTTPConnectionPool(host='localhost', port=8086): Max retries exceeded with url: /write?db=homeassistant (Caused by NewConnectionError('<urllib3.connection.HTTPConnection object at 0x71b00750>: Failed to establish a new connection: [Errno 111] Connection refused'))', please check your entries in the configuration file (host, port, etc.) and verify that the database exists and is READ/WRITE. Retrying again in 60 seconds.
2019-09-24 19:01:43 WARNING (SyncWorker_9) [homeassistant.components.influxdb] Database host is not accessible due to 'HTTPConnectionPool(host='localhost', port=8086): Max retries exceeded with url: /write?db=homeassistant (Caused by NewConnectionError('<urllib3.connection.HTTPConnection object at 0x71b0df10>: Failed to establish a new connection: [Errno 111] Connection refused'))', please check your entries in the configuration file (host, port, etc.) and verify that the database exists and is READ/WRITE. Retrying again in 60 seconds.
2019-09-24 19:02:44 WARNING (SyncWorker_17) [homeassistant.components.influxdb] Database host is not accessible due to 'HTTPConnectionPool(host='localhost', port=8086): Max retries exceeded with url: /write?db=homeassistant (Caused by NewConnectionError('<urllib3.connection.HTTPConnection object at 0x71b00670>: Failed to establish a new connection: [Errno 111] Connection refused'))', please check your entries in the configuration file (host, port, etc.) and verify that the database exists and is READ/WRITE. Retrying again in 60 seconds.
2019-09-24 19:03:45 WARNING (SyncWorker_19) [homeassistant.components.influxdb] Database host is not accessible due to 'HTTPConnectionPool(host='localhost', port=8086): Max retries exceeded with url: /write?db=homeassistant (Caused by NewConnectionError('<urllib3.connection.HTTPConnection object at 0x71b00a10>: Failed to establish a new connection: [Errno 111] Connection refused'))', please check your entries in the configuration file (host, port, etc.) and verify that the database exists and is READ/WRITE. Retrying again in 60 seconds.
2019-09-24 19:04:28 ERROR (MainThread) [aiohttp.server] Unhandled exception
Traceback (most recent call last):
  File "/usr/local/lib/python3.7/site-packages/aiohttp/web_protocol.py", line 447, in start
    await resp.prepare(request)
  File "/usr/local/lib/python3.7/site-packages/aiohttp/web_response.py", line 353, in prepare
    return await self._start(request)
  File "/usr/local/lib/python3.7/site-packages/aiohttp/web_response.py", line 667, in _start
    return await super()._start(request)
  File "/usr/local/lib/python3.7/site-packages/aiohttp/web_response.py", line 410, in _start
    await writer.write_headers(status_line, headers)
  File "/usr/local/lib/python3.7/site-packages/aiohttp/http_writer.py", line 112, in write_headers
    self._write(buf)
  File "/usr/local/lib/python3.7/site-packages/aiohttp/http_writer.py", line 67, in _write
    raise ConnectionResetError('Cannot write to closing transport')
ConnectionResetError: Cannot write to closing transport
2019-09-24 19:04:46 WARNING (SyncWorker_6) [homeassistant.components.influxdb] Database host is not accessible due to 'HTTPConnectionPool(host='localhost', port=8086): Max retries exceeded with url: /write?db=homeassistant (Caused by NewConnectionError('<urllib3.connection.HTTPConnection object at 0x71387e90>: Failed to establish a new connection: [Errno 111] Connection refused'))', please check your entries in the configuration file (host, port, etc.) and verify that the database exists and is READ/WRITE. Retrying again in 60 seconds.
2019-09-24 19:05:47 WARNING (SyncWorker_9) [homeassistant.components.influxdb] Database host is not accessible due to 'HTTPConnectionPool(host='localhost', port=8086): Max retries exceeded with url: /write?db=homeassistant (Caused by NewConnectionError('<urllib3.connection.HTTPConnection object at 0x71392bb0>: Failed to establish a new connection: [Errno 111] Connection refused'))', please check your entries in the configuration file (host, port, etc.) and verify that the database exists and is READ/WRITE. Retrying again in 60 seconds.
2019-09-24 19:06:48 WARNING (SyncWorker_6) [homeassistant.components.influxdb] Database host is not accessible due to 'HTTPConnectionPool(host='localhost', port=8086): Max retries exceeded with url: /write?db=homeassistant (Caused by NewConnectionError('<urllib3.connection.HTTPConnection object at 0x71387090>: Failed to establish a new connection: [Errno 111] Connection refused'))', please check your entries in the configuration file (host, port, etc.) and verify that the database exists and is READ/WRITE. Retrying again in 60 seconds.
2019-09-24 19:07:49 WARNING (SyncWorker_0) [homeassistant.components.influxdb] Database host is not accessible due to 'HTTPConnectionPool(host='localhost', port=8086): Max retries exceeded with url: /write?db=homeassistant (Caused by NewConnectionError('<urllib3.connection.HTTPConnection object at 0x7138fb30>: Failed to establish a new connection: [Errno 111] Connection refused'))', please check your entries in the configuration file (host, port, etc.) and verify that the database exists and is READ/WRITE. Retrying again in 60 seconds.
2019-09-24 19:08:50 WARNING (SyncWorker_15) [homeassistant.components.influxdb] Database host is not accessible due to 'HTTPConnectionPool(host='localhost', port=8086): Max retries exceeded with url: /write?db=homeassistant (Caused by NewConnectionError('<urllib3.connection.HTTPConnection object at 0x7138bfd0>: Failed to establish a new connection: [Errno 111] Connection refused'))', please check your entries in the configuration file (host, port, etc.) and verify that the database exists and is READ/WRITE. Retrying again in 60 seconds.
2019-09-24 19:09:51 WARNING (SyncWorker_4) [homeassistant.components.influxdb] Database host is not accessible due to 'HTTPConnectionPool(host='localhost', port=8086): Max retries exceeded with url: /write?db=homeassistant (Caused by NewConnectionError('<urllib3.connection.HTTPConnection object at 0x6e887190>: Failed to establish a new connection: [Errno 111] Connection refused'))', please check your entries in the configuration file (host, port, etc.) and verify that the database exists and is READ/WRITE. Retrying again in 60 seconds.
2019-09-24 19:10:52 WARNING (SyncWorker_17) [homeassistant.components.influxdb] Database host is not accessible due to 'HTTPConnectionPool(host='localhost', port=8086): Max retries exceeded with url: /write?db=homeassistant (Caused by NewConnectionError('<urllib3.connection.HTTPConnection object at 0x7138b8b0>: Failed to establish a new connection: [Errno 111] Connection refused'))', please check your entries in the configuration file (host, port, etc.) and verify that the database exists and is READ/WRITE. Retrying again in 60 seconds.
2019-09-24 19:11:53 WARNING (SyncWorker_2) [homeassistant.components.influxdb] Database host is not accessible due to 'HTTPConnectionPool(host='localhost', port=8086): Max retries exceeded with url: /write?db=homeassistant (Caused by NewConnectionError('<urllib3.connection.HTTPConnection object at 0x71b00a50>: Failed to establish a new connection: [Errno 111] Connection refused'))', please check your entries in the configuration file (host, port, etc.) and verify that the database exists and is READ/WRITE. Retrying again in 60 seconds.
